<?xml version="1.0" ?>
<!-- =================================================================================== -->
<!-- |    This document was autogenerated by xacro from locobot.urdf.xacro             | -->
<!-- |    EDITING THIS FILE BY HAND IS NOT RECOMMENDED                                 | -->
<!-- =================================================================================== -->
<robot name="locobot">
  <material name="interbotix_black">
    <texture filename="package://interbotix_xslocobot_descriptions/meshes/interbotix_black.png"/>
  </material>
  <link name="/base_footprint"/>
  <!-- Much of the following Kobuki description is taken from https://github.com/yujinrobot/kobuki/blob/23748ed3dfb082831ca8eaaef1a0b08588dbcb65/kobuki_description/urdf/kobuki.urdf.xacro -->
  <!-- It has been modified to include the robot_name as a prefix to the links -->
  <!-- The kobuki_description package is distributed under the 3-Clause BSD License, but no license file was found in the package. -->
  <!-- The license from the kobuki_node package is given from https://github.com/yujinrobot/kobuki/blob/8f2fa7b9e5e98c503ba468602c3a5dd9be68fc26/kobuki_node/LICENSE below: -->
  <!--
    # Software License Agreement (BSD License)
    #
    # Copyright (c) 2012 Yujin Robot, Daniel Stonier, Jorge Santos,
    # Marcus Liebhardt, Younghun Ju, Jihoon Lee
    # All rights reserved.
    #
    # Redistribution and use in source and binary forms, with or without
    # modification, are permitted provided that the following conditions
    # are met:
    #
    #    * Redistributions of source code must retain the above copyright
    #        notice, this list of conditions and the following disclaimer.
    #    * Redistributions in binary form must reproduce the above
    #        copyright notice, this list of conditions and the following
    #        disclaimer in the documentation and/or other materials provided
    #        with the distribution.
    #    * Neither the name of Yujin Robot nor the names of its
    #        contributors may be used to endorse or promote products derived
    #        from this software without specific prior written permission.
    #
    # THIS SOFTWARE IS PROVIDED BY THE COPYRIGHT HOLDERS AND CONTRIBUTORS
    # "AS IS" AND ANY EXPRESS OR IMPLIED WARRANTIES, INCLUDING, BUT NOT
    # LIMITED TO, THE IMPLIED WARRANTIES OF MERCHANTABILITY AND FITNESS
    # FOR A PARTICULAR PURPOSE ARE DISCLAIMED. IN NO EVENT SHALL THE
    # COPYRIGHT OWNER OR CONTRIBUTORS BE LIABLE FOR ANY DIRECT, INDIRECT,
    # INCIDENTAL, SPECIAL, EXEMPLARY, OR CONSEQUENTIAL DAMAGES (INCLUDING,
    # BUT NOT LIMITED TO, PROCUREMENT OF SUBSTITUTE GOODS OR SERVICES;
    # LOSS OF USE, DATA, OR PROFITS; OR BUSINESS INTERRUPTION) HOWEVER
    # CAUSED AND ON ANY THEORY OF LIABILITY, WHETHER IN CONTRACT, STRICT
    # LIABILITY, OR TORT (INCLUDING NEGLIGENCE OR OTHERWISE) ARISING IN
    # ANY WAY OUT OF THE USE OF THIS SOFTWARE, EVEN IF ADVISED OF THE
    # POSSIBILITY OF SUCH DAMAGE.
  -->
  <joint name="base_joint" type="fixed">
    <origin rpy="0 0 0" xyz="0 0 0.0102"/>
    <parent link="/base_footprint"/>
    <child link="/base_link"/>
  </joint>
  <link name="/base_link">
    <visual>
      <origin rpy="0 0 0" xyz="0.001 0 0.05199"/>
      <geometry>
        <mesh filename="package://interbotix_xslocobot_descriptions/meshes/locobot_meshes/kobuki_version/kobuki.dae"/>
      </geometry>
    </visual>
    <collision>
      <origin rpy="0 0 0" xyz="0.0 0 0.05949"/>
      <geometry>
        <cylinder length="0.10938" radius="0.178"/>
      </geometry>
    </collision>
    <inertial>
      <origin rpy="0 0 0" xyz="0.01 0 0"/>
      <mass value="2.4"/>
      <inertia ixx="0.019995" ixy="0.0" ixz="0.0" iyy="0.019995" iyz="0.0" izz="0.03675"/>
    </inertial>
  </link>
  <gazebo reference="/base_link">
    <mu1>0.3</mu1>
    <mu2>0.3</mu2>
    <sensor name="bumpers" type="contact">
      <always_on>1</always_on>
      <update_rate>50.0</update_rate>
      <visualize>true</visualize>
      <contact>
        <collision>base_footprint</collision>
      </contact>
    </sensor>
  </gazebo>
  <joint name="wheel_left_joint" type="continuous">
    <axis xyz="0 0 1"/>
    <origin rpy="-1.57079632679 0 0" xyz="0.00 0.115 0.0250"/>
    <parent link="/base_link"/>
    <child link="/wheel_left_link"/>
  </joint>
  <transmission name="trans_wheel_left_joint">
    <type>transmission_interface/SimpleTransmission</type>
    <joint name="wheel_left_joint">
      <hardwareInterface>hardware_interface/EffortJointInterface</hardwareInterface>
    </joint>
    <actuator name="wheel_left_joint_motor">
      <mechanicalReduction>1</mechanicalReduction>
    </actuator>
  </transmission>
  <link name="/wheel_left_link">
    <visual>
      <origin rpy="0 0 0" xyz="0 0 0"/>
      <geometry>
        <mesh filename="package://interbotix_xslocobot_descriptions/meshes/locobot_meshes/kobuki_version/kobuki_wheel.dae"/>
      </geometry>
    </visual>
    <collision>
      <geometry>
        <cylinder length="0.0206" radius="0.0352"/>
      </geometry>
      <origin rpy="0 0 0" xyz="0 0 0"/>
    </collision>
    <inertial>
      <origin xyz="0 0 0"/>
      <mass value="0.01"/>
      <inertia ixx="0.001" ixy="0.0" ixz="0.0" iyy="0.001" iyz="0.0" izz="0.001"/>
    </inertial>
  </link>
  <gazebo reference="/wheel_left_link">
    <mu1>1.0</mu1>
    <mu2>1.0</mu2>
    <kp>1000000.0</kp>
    <kd>100.0</kd>
    <minDepth>0.001</minDepth>
    <maxVel>1.0</maxVel>
  </gazebo>
  <joint name="wheel_right_joint" type="continuous">
    <axis xyz="0 0 1"/>
    <origin rpy="-1.57079632679 0 0" xyz="0.00 -0.115 0.0250"/>
    <parent link="/base_link"/>
    <child link="/wheel_right_link"/>
  </joint>
  <transmission name="trans_wheel_right_joint">
    <type>transmission_interface/SimpleTransmission</type>
    <joint name="wheel_right_joint">
      <hardwareInterface>hardware_interface/EffortJointInterface</hardwareInterface>
    </joint>
    <actuator name="wheel_right_joint_motor">
      <mechanicalReduction>1</mechanicalReduction>
    </actuator>
  </transmission>
  <link name="/wheel_right_link">
    <visual>
      <origin rpy="0 0 0" xyz="0 0 0"/>
      <geometry>
        <mesh filename="package://interbotix_xslocobot_descriptions/meshes/locobot_meshes/kobuki_version/kobuki_wheel.dae"/>
      </geometry>
    </visual>
    <collision>
      <origin rpy="0 0 0" xyz="0 0 0"/>
      <geometry>
        <cylinder length="0.0206" radius="0.0350"/>
      </geometry>
    </collision>
    <inertial>
      <origin xyz="0 0 0"/>
      <mass value="0.01"/>
      <inertia ixx="0.001" ixy="0.0" ixz="0.0" iyy="0.001" iyz="0.0" izz="0.001"/>
    </inertial>
  </link>
  <gazebo reference="/wheel_right_link">
    <mu1>1.0</mu1>
    <mu2>1.0</mu2>
    <kp>1000000.0</kp>
    <kd>100.0</kd>
    <minDepth>0.001</minDepth>
    <maxVel>1.0</maxVel>
  </gazebo>
  <joint name="caster_front_joint" type="fixed">
    <origin rpy="-1.57079632679 0 0" xyz="0.115 0.0 0.007"/>
    <parent link="/base_link"/>
    <child link="/caster_front_link"/>
  </joint>
  <link name="/caster_front_link">
    <collision>
      <origin rpy="0 0 0" xyz="0 0 0"/>
      <geometry>
        <cylinder length="0.0176" radius="0.017"/>
      </geometry>
    </collision>
    <inertial>
      <origin xyz="0 0 0"/>
      <mass value="0.01"/>
      <inertia ixx="0.001" ixy="0.0" ixz="0.0" iyy="0.001" iyz="0.0" izz="0.001"/>
    </inertial>
  </link>
  <gazebo reference="/caster_front_link">
    <mu1>0.0</mu1>
    <mu2>0.0</mu2>
    <kp>1000000.0</kp>
    <kd>100.0</kd>
    <minDepth>0.001</minDepth>
    <maxVel>1.0</maxVel>
  </gazebo>
  <joint name="caster_back_joint" type="fixed">
    <origin rpy="-1.57079632679 0 0" xyz="-0.135 0.0 0.009"/>
    <parent link="/base_link"/>
    <child link="/caster_back_link"/>
  </joint>
  <link name="/caster_back_link">
    <collision>
      <origin rpy="0 0 0" xyz="0 0 0"/>
      <geometry>
        <cylinder length="0.0176" radius="0.017"/>
      </geometry>
    </collision>
    <inertial>
      <origin xyz="0 0 0"/>
      <mass value="0.01"/>
      <inertia ixx="0.001" ixy="0.0" ixz="0.0" iyy="0.001" iyz="0.0" izz="0.001"/>
    </inertial>
  </link>
  <gazebo reference="/caster_back_link">
    <mu1>0.0</mu1>
    <mu2>0.0</mu2>
    <kp>1000000.0</kp>
    <kd>100.0</kd>
    <minDepth>0.001</minDepth>
    <maxVel>1.0</maxVel>
  </gazebo>
  <joint name="gyro_joint" type="fixed">
    <origin rpy="0 0 0" xyz="0.056 0.062 0.0202"/>
    <parent link="/base_link"/>
    <child link="/gyro_link"/>
  </joint>
  <link name="/gyro_link">
    <inertial>
      <origin rpy="0 0 0" xyz="0 0 0"/>
      <mass value="0.001"/>
      <inertia ixx="0.0001" ixy="0" ixz="0" iyy="0.000001" iyz="0" izz="0.0001"/>
    </inertial>
  </link>
  <gazebo reference="/gyro_link">
    <sensor name="imu" type="imu">
      <always_on>true</always_on>
      <update_rate>50</update_rate>
      <visualize>false</visualize>
      <imu>
        <noise>
          <type>gaussian</type>
          <rate>
            <mean>0.0</mean>
            <stddev>0.00000196</stddev>
            <!-- 0.25 x 0.25 (deg/s) -->
            <bias_mean>0.0</bias_mean>
            <bias_stddev>0.0</bias_stddev>
          </rate>
          <accel>
            <!-- not used in the plugin and real robot, hence using tutorial values -->
            <mean>0.0</mean>
            <stddev>1.7e-2</stddev>
            <bias_mean>0.1</bias_mean>
            <bias_stddev>0.001</bias_stddev>
          </accel>
        </noise>
      </imu>
    </sensor>
  </gazebo>
  <joint name="cliff_sensor_left_joint" type="fixed">
    <origin rpy="0 1.57079632679 0" xyz="0.08734 0.13601 0.0214"/>
    <parent link="/base_link"/>
    <child link="/cliff_sensor_left_link"/>
  </joint>
  <link name="/cliff_sensor_left_link">
    <inertial>
      <mass value="0.0001"/>
      <origin xyz="0 0 0"/>
      <inertia ixx="0.0001" ixy="0.0" ixz="0.0" iyy="0.0001" iyz="0.0" izz="0.0001"/>
    </inertial>
  </link>
  <gazebo reference="/cliff_sensor_left_link">
    <sensor name="cliff_sensor_left" type="ray">
      <always_on>true</always_on>
      <update_rate>50</update_rate>
      <visualize>true</visualize>
      <ray>
        <scan>
          <horizontal>
            <samples>50</samples>
            <resolution>1.0</resolution>
            <min_angle>-0.0436</min_angle>
            <!-- -2.5 degree -->
            <max_angle>0.0436</max_angle>
            <!-- 2.5 degree -->
          </horizontal>
        </scan>
        <range>
          <min>0.01</min>
          <max>0.15</max>
          <resolution>1.0</resolution>
        </range>
      </ray>
    </sensor>
  </gazebo>
  <joint name="cliff_sensor_right_joint" type="fixed">
    <origin rpy="0 1.57079632679 0" xyz="0.085 -0.13601 0.0214"/>
    <parent link="/base_link"/>
    <child link="/cliff_sensor_right_link"/>
  </joint>
  <link name="/cliff_sensor_right_link">
    <inertial>
      <origin xyz="0 0 0"/>
      <mass value="0.0001"/>
      <inertia ixx="0.0001" ixy="0.0" ixz="0.0" iyy="0.0001" iyz="0.0" izz="0.0001"/>
    </inertial>
  </link>
  <gazebo reference="/cliff_sensor_right_link">
    <sensor name="cliff_sensor_right" type="ray">
      <always_on>true</always_on>
      <update_rate>50</update_rate>
      <visualize>true</visualize>
      <ray>
        <scan>
          <horizontal>
            <samples>50</samples>
            <resolution>1.0</resolution>
            <min_angle>-0.0436</min_angle>
            <!-- -2.5 degree -->
            <max_angle>0.0436</max_angle>
            <!-- 2.5 degree -->
          </horizontal>
        </scan>
        <range>
          <min>0.01</min>
          <max>0.15</max>
          <resolution>1.0</resolution>
        </range>
      </ray>
    </sensor>
  </gazebo>
  <joint name="cliff_sensor_front_joint" type="fixed">
    <origin rpy="0 1.57079632679 0" xyz="0.156 0.00 0.0214"/>
    <parent link="/base_link"/>
    <child link="/cliff_sensor_front_link"/>
  </joint>
  <link name="/cliff_sensor_front_link">
    <inertial>
      <mass value="0.0001"/>
      <origin xyz="0 0 0"/>
      <inertia ixx="0.0001" ixy="0.0" ixz="0.0" iyy="0.0001" iyz="0.0" izz="0.0001"/>
    </inertial>
  </link>
  <gazebo reference="/cliff_sensor_front_link">
    <sensor name="cliff_sensor_front" type="ray">
      <always_on>true</always_on>
      <update_rate>50</update_rate>
      <visualize>true</visualize>
      <ray>
        <scan>
          <horizontal>
            <samples>50</samples>
            <resolution>1.0</resolution>
            <min_angle>-0.0436</min_angle>
            <!-- -2.5 degree -->
            <max_angle>0.0436</max_angle>
            <!-- 2.5 degree -->
          </horizontal>
        </scan>
        <range>
          <min>0.01</min>
          <max>0.15</max>
          <resolution>1.0</resolution>
        </range>
      </ray>
    </sensor>
  </gazebo>
  <!-- Plugins -->
  <gazebo>
    <!-- Gazebo ROS Control -->
    <plugin filename="libgazebo_ros_control.so" name="gazebo_ros_control">
      <robotSimType>gazebo_ros_control/DefaultRobotHWSim</robotSimType>
      <legacyModeNS>true</legacyModeNS>
    </plugin>
    <!-- Differential Drive -->
    <plugin filename="libgazebo_ros_diff_drive.so" name="differential_drive_controller">
      <alwaysOn>true</alwaysOn>
      <legacyMode>false</legacyMode>
      <updateRate>30</updateRate>
      <leftJoint>wheel_left_joint</leftJoint>
      <rightJoint>wheel_right_joint</rightJoint>
      <wheelSeparation>0.230</wheelSeparation>
      <wheelDiameter>0.070</wheelDiameter>
      <wheelTorque>1.0</wheelTorque>
      <wheelAcceleration>0</wheelAcceleration>
      <commandTopic>mobile_base/commands/velocity</commandTopic>
      <odometryTopic>mobile_base/odom</odometryTopic>
      <odometryFrame>/odom</odometryFrame>
      <robotBaseFrame>/base_footprint</robotBaseFrame>
      <publishWheelJointState>true</publishWheelJointState>
      <rosDebugLevel>na</rosDebugLevel>
      <publishWheelTF>false</publishWheelTF>
      <publishOdomTF>true</publishOdomTF>
      <odometrySource>world</odometrySource>
      <publishTf>1</publishTf>
    </plugin>
    <!-- Ground truth pose -->
    <plugin filename="libgazebo_ros_p3d.so" name="p3d_base_controller">
      <alwaysOn>true</alwaysOn>
      <updateRate>100.0</updateRate>
      <bodyName>/base_link</bodyName>
      <topicName>mobile_base/absolute_position</topicName>
      <gaussianNoise>0</gaussianNoise>
      <frameName>map</frameName>
      <xyzOffsets>0 0 0</xyzOffsets>
      <rpyOffsets>0 0 0</rpyOffsets>
      <!--<interface:position name="p3d_base_position"/>-->
    </plugin>
  </gazebo>
  <!-- kobuki -->
  <!-- create3 -->
  <!-- ********************************** Plate **********************************  -->
  <joint name="plate" type="fixed">
    <origin rpy="0 0 0" xyz="0.0 0 0.08825"/>
    <parent link="/base_link"/>
    <child link="/plate_link"/>
  </joint>
  <link name="/plate_link">
    <visual>
      <origin rpy="0 0 0" xyz="0 0 0"/>
      <geometry>
        <mesh filename="package://interbotix_xslocobot_descriptions/meshes/locobot_meshes/kobuki_version/locobot_base_plate.stl" scale="0.001 0.001 0.001"/>
      </geometry>
      <material name="interbotix_black"/>
    </visual>
    <collision>
      <origin rpy="0 0 0" xyz="0 0 0"/>
      <geometry>
        <mesh filename="package://interbotix_xslocobot_descriptions/meshes/locobot_meshes/kobuki_version/locobot_base_plate.stl" scale="0.001 0.001 0.001"/>
      </geometry>
    </collision>
    <inertial>
      <origin rpy="0 0 0" xyz="0.050816 0 0.00475"/>
      <mass value="0.571995"/>
      <inertia ixx="0.003115" ixy="0" ixz="0" iyy="0.001813" iyz="0" izz="0.004919"/>
    </inertial>
  </link>
  <gazebo reference="/plate_link">
    <material>Custom/Interbotix</material>
  </gazebo>
  <!-- base_type == 'kobuki' -->
  <!-- base_type == 'create3' -->
  <!-- ********************************** Arm ********************************** -->
  <joint name="arm_base_link_joint" type="fixed">
    <axis xyz="0 0 0"/>
    <origin rpy="0 0 0" xyz="0.097277 0 0.0095"/>
    <!-- arm_type != 'mobile_px100' -->
    <parent link="/plate_link"/>
    <child link="/arm_base_link"/>
  </joint>
  <!-- base_type == 'kobuki' -->
  <!-- base_type == 'create3' -->
  <link name="/arm_base_link">
    <visual>
      <origin rpy="1.5707963267948966 0 1.5707963267948966" xyz="-0.095773 0 -0.10565023"/>
      <geometry>
        <mesh filename="package://interbotix_xslocobot_descriptions/meshes/mobile_wx200_meshes/mobile_wx200_1_base.stl" scale="0.001 0.001 0.001"/>
      </geometry>
      <material name="interbotix_black"/>
    </visual>
    <collision>
      <origin rpy="1.5707963267948966 0 1.5707963267948966" xyz="-0.095773 0 -0.10565023"/>
      <geometry>
        <mesh filename="package://interbotix_xslocobot_descriptions/meshes/mobile_wx200_meshes/mobile_wx200_1_base.stl" scale="0.001 0.001 0.001"/>
      </geometry>
    </collision>
    <inertial>
      <origin rpy="1.5707963267948966 0 1.5707963267948966" xyz="-0.0001350000 -0.0000266286 0.0338755000"/>
      <mass value="0.379673"/>
      <inertia ixx="0.0004351000" ixy="0.0000000707" ixz="0.0000000266" iyy="0.0004452000" iyz="-0.0000022881" izz="0.0005731000"/>
    </inertial>
  </link>
  <joint name="waist" type="revolute">
    <axis xyz="0 0 1"/>
    <limit effort="8" lower="-3.141582653589793" upper="3.141582653589793" velocity="3.141592653589793"/>
    <origin rpy="0 0 0" xyz="0 0 0.066175"/>
    <parent link="/arm_base_link"/>
    <child link="/shoulder_link"/>
    <dynamics friction="0.1"/>
  </joint>
  <transmission name="trans_waist">
    <type>transmission_interface/SimpleTransmission</type>
    <joint name="waist">
      <hardwareInterface>hardware_interface/EffortJointInterface</hardwareInterface>
    </joint>
    <actuator name="waist_motor">
      <mechanicalReduction>1</mechanicalReduction>
    </actuator>
  </transmission>
  <link name="/shoulder_link">
    <visual>
      <origin rpy="0 0 1.5707963267948966" xyz="0 0 -0.003"/>
      <geometry>
        <mesh filename="package://interbotix_xslocobot_descriptions/meshes/mobile_wx200_meshes/mobile_wx200_2_shoulder.stl" scale="0.001 0.001 0.001"/>
      </geometry>
      <material name="interbotix_black"/>
    </visual>
    <collision>
      <origin rpy="0 0 1.5707963267948966" xyz="0 0 -0.003"/>
      <geometry>
        <mesh filename="package://interbotix_xslocobot_descriptions/meshes/mobile_wx200_meshes/mobile_wx200_2_shoulder.stl" scale="0.001 0.001 0.001"/>
      </geometry>
    </collision>
    <inertial>
      <origin rpy="0 0 1.5707963267948966" xyz="0.0000223210 0.0000414608 0.0066287000"/>
      <mass value="0.480879"/>
      <inertia ixx="0.0003790000" ixy="0.0000000022" ixz="-0.0000003561" iyy="0.0005557000" iyz="0.0000012247" izz="0.0005889000"/>
    </inertial>
  </link>
  <joint name="shoulder" type="revolute">
    <axis xyz="0 1 0"/>
    <limit effort="18" lower="-1.8849555921538759" upper="1.9722220547535925" velocity="3.141592653589793"/>
    <origin rpy="0 0 0" xyz="0 0 0.03865"/>
    <parent link="/shoulder_link"/>
    <child link="/upper_arm_link"/>
    <dynamics friction="0.1"/>
  </joint>
  <transmission name="trans_shoulder">
    <type>transmission_interface/SimpleTransmission</type>
    <joint name="shoulder">
      <hardwareInterface>hardware_interface/EffortJointInterface</hardwareInterface>
    </joint>
    <actuator name="shoulder_motor">
      <mechanicalReduction>1</mechanicalReduction>
    </actuator>
  </transmission>
  <link name="/upper_arm_link">
    <visual>
      <origin rpy="0 0 1.5707963267948966" xyz="0 0 0"/>
      <geometry>
        <mesh filename="package://interbotix_xslocobot_descriptions/meshes/mobile_wx200_meshes/mobile_wx200_3_upper_arm.stl" scale="0.001 0.001 0.001"/>
      </geometry>
      <material name="interbotix_black"/>
    </visual>
    <collision>
      <origin rpy="0 0 1.5707963267948966" xyz="0 0 0"/>
      <geometry>
        <mesh filename="package://interbotix_xslocobot_descriptions/meshes/mobile_wx200_meshes/mobile_wx200_3_upper_arm.stl" scale="0.001 0.001 0.001"/>
      </geometry>
    </collision>
    <inertial>
      <origin rpy="0 0 1.5707963267948966" xyz="0.0119707000 -0.0001179264 0.1394290000"/>
      <mass value="0.297781"/>
      <inertia ixx="0.0017100000" ixy="-0.0000011433" ixz="0.0000021161" iyy="0.0016310000" iyz="0.0002135000" izz="0.0001482000"/>
    </inertial>
  </link>
  <joint name="elbow" type="revolute">
    <axis xyz="0 1 0"/>
    <limit effort="13" lower="-1.8849555921538759" upper="1.6231562043547265" velocity="3.141592653589793"/>
    <origin rpy="0 0 0" xyz="0.05 0 0.2"/>
    <parent link="/upper_arm_link"/>
    <child link="/forearm_link"/>
    <dynamics friction="0.1"/>
  </joint>
  <transmission name="trans_elbow">
    <type>transmission_interface/SimpleTransmission</type>
    <joint name="elbow">
      <hardwareInterface>hardware_interface/EffortJointInterface</hardwareInterface>
    </joint>
    <actuator name="elbow_motor">
      <mechanicalReduction>1</mechanicalReduction>
    </actuator>
  </transmission>
  <link name="/forearm_link">
    <visual>
      <origin rpy="0 0 1.5707963267948966" xyz="0 0 0"/>
      <geometry>
        <mesh filename="package://interbotix_xslocobot_descriptions/meshes/mobile_wx200_meshes/mobile_wx200_4_forearm.stl" scale="0.001 0.001 0.001"/>
      </geometry>
      <material name="interbotix_black"/>
    </visual>
    <collision>
      <origin rpy="0 0 1.5707963267948966" xyz="0 0 0"/>
      <geometry>
        <mesh filename="package://interbotix_xslocobot_descriptions/meshes/mobile_wx200_meshes/mobile_wx200_4_forearm.stl" scale="0.001 0.001 0.001"/>
      </geometry>
    </collision>
    <inertial>
      <origin rpy="0 0 1.5707963267948966" xyz="0.1211920000 -0.0001238123 0.0000000000"/>
      <mass value="0.283651"/>
      <inertia ixx="0.0011850000" ixy="-0.0000024317" ixz="0.0000000000" iyy="0.0000682900" iyz="0.0000000000" izz="0.0012060000"/>
    </inertial>
  </link>
  <joint name="wrist_angle" type="revolute">
    <axis xyz="0 1 0"/>
    <limit effort="5" lower="-1.7453292519943295" upper="2.1467549799530254" velocity="3.141592653589793"/>
    <origin rpy="0 0 0" xyz="0.2 0 0"/>
    <parent link="/forearm_link"/>
    <child link="/wrist_link"/>
    <dynamics friction="0.1"/>
  </joint>
  <transmission name="trans_wrist_angle">
    <type>transmission_interface/SimpleTransmission</type>
    <joint name="wrist_angle">
      <hardwareInterface>hardware_interface/EffortJointInterface</hardwareInterface>
    </joint>
    <actuator name="wrist_angle_motor">
      <mechanicalReduction>1</mechanicalReduction>
    </actuator>
  </transmission>
  <link name="/wrist_link">
    <visual>
      <origin rpy="0 0 1.5707963267948966" xyz="0 0 0"/>
      <geometry>
        <mesh filename="package://interbotix_xslocobot_descriptions/meshes/mobile_wx200_meshes/mobile_wx200_5_wrist.stl" scale="0.001 0.001 0.001"/>
      </geometry>
      <material name="interbotix_black"/>
    </visual>
    <collision>
      <origin rpy="0 0 1.5707963267948966" xyz="0 0 0"/>
      <geometry>
        <mesh filename="package://interbotix_xslocobot_descriptions/meshes/mobile_wx200_meshes/mobile_wx200_5_wrist.stl" scale="0.001 0.001 0.001"/>
      </geometry>
    </collision>
    <inertial>
      <origin rpy="0 0 1.5707963267948966" xyz="0.0423600000 -0.0000106630 0.0105770000"/>
      <mass value="0.084957"/>
      <inertia ixx="0.0000308200" ixy="0.0000000191" ixz="0.0000000023" iyy="0.0000282200" iyz="0.0000025481" izz="0.0000315200"/>
    </inertial>
  </link>
  <joint name="wrist_rotate" type="revolute">
    <axis xyz="1 0 0"/>
    <limit effort="1" lower="-3.141582653589793" upper="3.141582653589793" velocity="3.141592653589793"/>
    <origin rpy="0 0 0" xyz="0.065 0 0"/>
    <parent link="/wrist_link"/>
    <child link="/gripper_link"/>
    <dynamics friction="0.1"/>
  </joint>
  <transmission name="trans_wrist_rotate">
    <type>transmission_interface/SimpleTransmission</type>
    <joint name="wrist_rotate">
      <hardwareInterface>hardware_interface/EffortJointInterface</hardwareInterface>
    </joint>
    <actuator name="wrist_rotate_motor">
      <mechanicalReduction>1</mechanicalReduction>
    </actuator>
  </transmission>
  <link name="/gripper_link">
    <visual>
      <origin rpy="0 0 1.5707963267948966" xyz="-0.02 0 0"/>
      <geometry>
        <mesh filename="package://interbotix_xslocobot_descriptions/meshes/mobile_wx200_meshes/mobile_wx200_6_gripper.stl" scale="0.001 0.001 0.001"/>
      </geometry>
      <material name="interbotix_black"/>
    </visual>
    <collision>
      <origin rpy="0 0 1.5707963267948966" xyz="-0.02 0 0"/>
      <geometry>
        <mesh filename="package://interbotix_xslocobot_descriptions/meshes/mobile_wx200_meshes/mobile_wx200_6_gripper.stl" scale="0.001 0.001 0.001"/>
      </geometry>
    </collision>
    <inertial>
      <origin rpy="0 0 1.5707963267948966" xyz="0.0216310000 0.0000002516 0.0114100000"/>
      <mass value="0.072885"/>
      <inertia ixx="0.0000253700" ixy="0.0000000000" ixz="0.0000000000" iyy="0.0000183600" iyz="0.0000004340" izz="0.0000167400"/>
    </inertial>
  </link>
  <joint name="ee_arm" type="fixed">
    <axis xyz="1 0 0"/>
    <origin rpy="0 0 0" xyz="0.043 0 0"/>
    <parent link="/gripper_link"/>
    <child link="/ee_arm_link"/>
  </joint>
  <link name="/ee_arm_link">
    <inertial>
      <mass value="0.001"/>
      <inertia ixx="0.001" ixy="0" ixz="0" iyy="0.001" iyz="0" izz="0.001"/>
    </inertial>
  </link>
  <joint name="gripper" type="continuous">
    <axis xyz="1 0 0"/>
    <limit effort="1" velocity="3.141592653589793"/>
    <origin rpy="0 0 0" xyz="0.0055 0 0"/>
    <parent link="/ee_arm_link"/>
    <child link="/gripper_prop_link"/>
    <dynamics friction="0.1"/>
  </joint>
  <transmission name="trans_gripper">
    <type>transmission_interface/SimpleTransmission</type>
    <joint name="gripper">
      <hardwareInterface>hardware_interface/EffortJointInterface</hardwareInterface>
    </joint>
    <actuator name="gripper_motor">
      <mechanicalReduction>1</mechanicalReduction>
    </actuator>
  </transmission>
  <link name="/gripper_prop_link">
    <visual>
      <origin rpy="0 0 1.5707963267948966" xyz="-0.0685 0 0"/>
      <geometry>
        <mesh filename="package://interbotix_xslocobot_descriptions/meshes/mobile_wx200_meshes/mobile_wx200_7_gripper_prop.stl" scale="0.001 0.001 0.001"/>
      </geometry>
      <material name="interbotix_black"/>
    </visual>
    <collision>
      <origin rpy="0 0 1.5707963267948966" xyz="-0.0685 0 0"/>
      <geometry>
        <mesh filename="package://interbotix_xslocobot_descriptions/meshes/mobile_wx200_meshes/mobile_wx200_7_gripper_prop.stl" scale="0.001 0.001 0.001"/>
      </geometry>
    </collision>
    <inertial>
      <origin rpy="0 0 1.5707963267948966" xyz="0.0008460000 -0.0000016817 0.0000420000"/>
      <mass value="0.00434"/>
      <inertia ixx="0.0000005923" ixy="0.0000000000" ixz="0.0000003195" iyy="0.0000011156" iyz="-0.0000000004" izz="0.0000005743"/>
    </inertial>
  </link>
  <joint name="ar_tag" type="fixed">
    <axis xyz="0 0 0"/>
    <origin rpy="0 0 0" xyz="-0.017 0 0.04155"/>
    <parent link="/ee_arm_link"/>
    <child link="/ar_tag_link"/>
  </joint>
  <link name="/ar_tag_link">
    <visual>
      <origin rpy="0 0 0" xyz="0 0 0"/>
      <geometry>
        <mesh filename="package://interbotix_xslocobot_descriptions/meshes/mobile_wx200_meshes/mobile_wx200_10_ar_tag.stl" scale="0.001 0.001 0.001"/>
      </geometry>
      <material name="interbotix_black"/>
    </visual>
    <collision>
      <origin rpy="0 0 0" xyz="0 0 0"/>
      <geometry>
        <mesh filename="package://interbotix_xslocobot_descriptions/meshes/mobile_wx200_meshes/mobile_wx200_10_ar_tag.stl" scale="0.001 0.001 0.001"/>
      </geometry>
    </collision>
    <inertial>
      <origin rpy="0 0 0" xyz="0 0 -0.00315"/>
      <mass value="0.016507"/>
      <inertia ixx="0.000003084" ixy="0" ixz="0" iyy="0.000003084" iyz="0" izz="0.000006059"/>
    </inertial>
  </link>
  <!-- If the gripper bar is being used, then also add the gripper bar -->
  <joint name="gripper_bar" type="fixed">
    <axis xyz="1 0 0"/>
    <origin rpy="0 0 0" xyz="0 0 0"/>
    <parent link="/ee_arm_link"/>
    <child link="/gripper_bar_link"/>
  </joint>
  <link name="/gripper_bar_link">
    <visual>
      <origin rpy="0 0 1.5707963267948966" xyz="-0.063 0 0"/>
      <geometry>
        <mesh filename="package://interbotix_xslocobot_descriptions/meshes/mobile_wx200_meshes/mobile_wx200_8_gripper_bar.stl" scale="0.001 0.001 0.001"/>
      </geometry>
      <material name="interbotix_black"/>
    </visual>
    <collision>
      <origin rpy="0 0 1.5707963267948966" xyz="-0.063 0 0"/>
      <geometry>
        <mesh filename="package://interbotix_xslocobot_descriptions/meshes/mobile_wx200_meshes/mobile_wx200_8_gripper_bar.stl" scale="0.001 0.001 0.001"/>
      </geometry>
    </collision>
    <inertial>
      <origin rpy="0 0 1.5707963267948966" xyz="0.0096870000 0.0000008177 0.0049620000"/>
      <mass value="0.034199"/>
      <inertia ixx="0.0000074125" ixy="-0.0000000008" ixz="-0.0000000006" iyy="0.0000284300" iyz="-0.0000013889" izz="0.0000286000"/>
    </inertial>
  </link>
  <joint name="ee_bar" type="fixed">
    <axis xyz="1 0 0"/>
    <origin rpy="0 0 0" xyz="0.023 0 0"/>
    <parent link="/gripper_bar_link"/>
    <child link="/fingers_link"/>
  </joint>
  <link name="/fingers_link">
    <inertial>
      <mass value="0.001"/>
      <inertia ixx="0.001" ixy="0" ixz="0" iyy="0.001" iyz="0" izz="0.001"/>
    </inertial>
  </link>
  <!-- If the gripper fingers are being used, add those as well -->
  <joint name="left_finger" type="prismatic">
    <axis xyz="0 1 0"/>
    <limit effort="5" lower="0.015" upper="0.037" velocity="1"/>
    <origin rpy="0 0 0" xyz="0 0 0"/>
    <parent link="/fingers_link"/>
    <child link="/left_finger_link"/>
    <dynamics friction="0.1"/>
  </joint>
  <transmission name="trans_left_finger">
    <type>transmission_interface/SimpleTransmission</type>
    <joint name="left_finger">
      <hardwareInterface>hardware_interface/EffortJointInterface</hardwareInterface>
    </joint>
    <actuator name="left_finger_motor">
      <mechanicalReduction>1</mechanicalReduction>
    </actuator>
  </transmission>
  <link name="/left_finger_link">
    <visual>
      <origin rpy="3.141592653589793 3.141592653589793 0" xyz="0 0.005 0"/>
      <geometry>
        <mesh filename="package://interbotix_xslocobot_descriptions/meshes/mobile_wx200_meshes/mobile_wx200_9_gripper_finger.stl" scale="0.001 0.001 0.001"/>
      </geometry>
      <material name="interbotix_black"/>
    </visual>
    <collision>
      <origin rpy="3.141592653589793 3.141592653589793 0" xyz="0 0.005 0"/>
      <geometry>
        <mesh filename="package://interbotix_xslocobot_descriptions/meshes/mobile_wx200_meshes/mobile_wx200_9_gripper_finger.stl" scale="0.001 0.001 0.001"/>
      </geometry>
    </collision>
    <inertial>
      <origin rpy="3.141592653589793 3.141592653589793 1.5707963267948966" xyz="0.0138160000 0.0000000000 0.0000000000"/>
      <mass value="0.016246"/>
      <inertia ixx="0.0000047310" ixy="-0.0000004560" ixz="0.0000000000" iyy="0.0000015506" iyz="0.0000000000" izz="0.0000037467"/>
    </inertial>
  </link>
  <joint name="right_finger" type="prismatic">
    <axis xyz="0 1 0"/>
    <limit effort="5" lower="-0.037" upper="-0.015" velocity="1"/>
    <origin rpy="0 0 0" xyz="0 0 0"/>
    <parent link="/fingers_link"/>
    <child link="/right_finger_link"/>
    <dynamics friction="0.1"/>
    <mimic joint="left_finger" multiplier="-1" offset="0"/>
  </joint>
  <transmission name="trans_right_finger">
    <type>transmission_interface/SimpleTransmission</type>
    <joint name="right_finger">
      <hardwareInterface>hardware_interface/EffortJointInterface</hardwareInterface>
    </joint>
    <actuator name="right_finger_motor">
      <mechanicalReduction>1</mechanicalReduction>
    </actuator>
  </transmission>
  <link name="/right_finger_link">
    <visual>
      <origin rpy="0 3.141592653589793 0" xyz="0 -0.005 0"/>
      <geometry>
        <mesh filename="package://interbotix_xslocobot_descriptions/meshes/mobile_wx200_meshes/mobile_wx200_9_gripper_finger.stl" scale="0.001 0.001 0.001"/>
      </geometry>
      <material name="interbotix_black"/>
    </visual>
    <collision>
      <origin rpy="0 3.141592653589793 0" xyz="0 -0.005 0"/>
      <geometry>
        <mesh filename="package://interbotix_xslocobot_descriptions/meshes/mobile_wx200_meshes/mobile_wx200_9_gripper_finger.stl" scale="0.001 0.001 0.001"/>
      </geometry>
    </collision>
    <inertial>
      <origin rpy="0 3.141592653589793 1.5707963267948966" xyz="0.0138160000 0.0000000000  0.0000000000"/>
      <mass value="0.016246"/>
      <inertia ixx="0.0000047310" ixy="0.0000004560" ixz="0.0000000000" iyy="0.0000015506" iyz="0.0000000000" izz="0.0000037467"/>
    </inertial>
  </link>
  <joint name="ee_gripper" type="fixed">
    <axis xyz="1 0 0"/>
    <origin rpy="0 0 0" xyz="0.027575 0 0"/>
    <parent link="/fingers_link"/>
    <child link="/ee_gripper_link"/>
  </joint>
  <link name="/ee_gripper_link">
    <inertial>
      <mass value="0.001"/>
      <inertia ixx="0.001" ixy="0" ixz="0" iyy="0.001" iyz="0" izz="0.001"/>
    </inertial>
  </link>
  <gazebo reference="/arm_base_link">
    <material>Custom/Interbotix</material>
    <dampingFactor>0.01</dampingFactor>
  </gazebo>
  <gazebo reference="/shoulder_link">
    <material>Custom/Interbotix</material>
    <dampingFactor>0.01</dampingFactor>
    <self_collide>true</self_collide>
  </gazebo>
  <gazebo reference="/upper_arm_link">
    <material>Custom/Interbotix</material>
    <dampingFactor>0.01</dampingFactor>
    <self_collide>true</self_collide>
  </gazebo>
  <gazebo reference="/forearm_link">
    <material>Custom/Interbotix</material>
    <dampingFactor>0.01</dampingFactor>
    <self_collide>true</self_collide>
  </gazebo>
  <gazebo reference="/upper_forearm_link">
    <material>Custom/Interbotix</material>
    <dampingFactor>0.01</dampingFactor>
    <self_collide>true</self_collide>
  </gazebo>
  <gazebo reference="/lower_forearm_link">
    <material>Custom/Interbotix</material>
    <dampingFactor>0.01</dampingFactor>
    <self_collide>true</self_collide>
  </gazebo>
  <gazebo reference="/wrist_link">
    <material>Custom/Interbotix</material>
    <dampingFactor>0.01</dampingFactor>
    <self_collide>true</self_collide>
  </gazebo>
  <gazebo reference="/gripper_link">
    <material>Custom/Interbotix</material>
    <dampingFactor>0.01</dampingFactor>
  </gazebo>
  <gazebo reference="/ar_tag_link">
    <material>Custom/Interbotix</material>
  </gazebo>
  <gazebo reference="/gripper_prop_link">
    <dampingFactor>0.01</dampingFactor>
    <material>Custom/Interbotix</material>
  </gazebo>
  <gazebo reference="/gripper_bar_link">
    <material>Custom/Interbotix</material>
  </gazebo>
  <gazebo reference="/left_finger_link">
    <material>Custom/Interbotix</material>
    <dampingFactor>0.01</dampingFactor>
  </gazebo>
  <gazebo reference="/right_finger_link">
    <material>Custom/Interbotix</material>
    <dampingFactor>0.01</dampingFactor>
  </gazebo>
  <gazebo reference="/arm_cradle_link">
    <material>Custom/Interbotix</material>
  </gazebo>
  <gazebo reference="arm_base_link_joint">
    <disableFixedJointLumping>true</disableFixedJointLumping>
  </gazebo>
  <gazebo reference="plate">
    <disableFixedJointLumping>true</disableFixedJointLumping>
  </gazebo>
  <gazebo reference="ar_tag">
    <disableFixedJointLumping>true</disableFixedJointLumping>
  </gazebo>
  <gazebo reference="ee_arm">
    <disableFixedJointLumping>true</disableFixedJointLumping>
  </gazebo>
  <gazebo reference="gripper_bar">
    <disableFixedJointLumping>true</disableFixedJointLumping>
  </gazebo>
  <gazebo reference="ee_bar">
    <disableFixedJointLumping>true</disableFixedJointLumping>
  </gazebo>
  <gazebo reference="ee_gripper">
    <disableFixedJointLumping>true</disableFixedJointLumping>
  </gazebo>
  <!--<xacro:if value="${arm_type == 'mobile_wx200'}">-->
  <joint name="arm_cradle" type="fixed">
    <axis xyz="0 0 0"/>
    <origin rpy="0 0 0" xyz="0.0215 0 0.1195"/>
    <parent link="locobot/camera_tower_link"/>
    <child link="locobot/arm_cradle_link"/>
  </joint>
  <link name="locobot/arm_cradle_link">
    <visual>
      <origin rpy="0 0 0" xyz="0 0 0"/>
      <geometry>
        <mesh filename="package://interbotix_xslocobot_descriptions/meshes/locobot_meshes/locobot_arm_cradle.stl" scale="0.001 0.001 0.001"/>
      </geometry>
      <material name="interbotix_black"/>
    </visual>
    <collision>
      <origin rpy="0 0 0" xyz="0 0 0"/>
      <geometry>
        <mesh filename="package://interbotix_xslocobot_descriptions/meshes/locobot_meshes/locobot_arm_cradle.stl" scale="0.001 0.001 0.001"/>
      </geometry>
    </collision>
    <inertial>
      <origin rpy="0 0 0" xyz="0.0014389900 0 0.0098387400"/>
      <mass value="0.017626"/>
      <inertia ixx="0.0000046575" ixy="0" ixz="0.0000000748" iyy="0.0000018629" iyz="0" izz="0.0000046198"/>
    </inertial>
  </link>
  <!--</xacro:if>-->
  <gazebo reference="arm_cradle">
    <disableFixedJointLumping>true</disableFixedJointLumping>
  </gazebo>
  <!-- base_type == 'kobuki' -->
  <!-- base_type == 'create3' -->
  <!-- arm_type == 'mobile_wx200' -->
  <!-- arm_type != 'mobile_base' -->
  <!-- ********************************** Battery **********************************  -->
  <joint name="battery" type="fixed">
    <origin rpy="0 0 0" xyz="-0.007 0 0.0125"/>
    <parent link="/plate_link"/>
    <child link="/battery_link"/>
  </joint>
  <gazebo reference="battery">
    <disableFixedJointLumping>true</disableFixedJointLumping>
  </gazebo>
  <link name="/battery_link">
    <visual>
      <origin rpy="0 0 0" xyz="0 0 0"/>
      <geometry>
        <mesh filename="package://interbotix_xslocobot_descriptions/meshes/locobot_meshes/locobot_battery.stl" scale="0.001 0.001 0.001"/>
      </geometry>
      <material name="">
        <color rgba="0.5 0.5 0.5 1"/>
      </material>
    </visual>
    <collision>
      <origin rpy="0 0 0" xyz="0 0 0"/>
      <geometry>
        <mesh filename="package://interbotix_xslocobot_descriptions/meshes/locobot_meshes/locobot_battery.stl" scale="0.001 0.001 0.001"/>
      </geometry>
    </collision>
    <inertial>
      <origin rpy="0 0 0" xyz="0 0 0.016"/>
      <mass value="1.194"/>
      <inertia ixx="0.004312" ixy="0" ixz="0" iyy="0.001908" iyz="0" izz="0.006017"/>
    </inertial>
  </link>
  <gazebo reference="/battery_link">
    <material>Gazebo/Grey</material>
  </gazebo>
  <!-- base_type == 'kobuki' -->
  <!-- base_type == 'create3' -->
  <!-- ********************************** Camera Tower **********************************  -->
  <!-- base_type == 'kobuki' && camera_tower_size == 'large' -->
  <joint name="camera_tower" type="fixed">
    <origin rpy="0 0 0" xyz="-0.023997 -0.000044 0.08823"/>
    <parent link="/base_link"/>
    <child link="/camera_tower_link"/>
  </joint>
  <gazebo reference="camera_tower">
    <disableFixedJointLumping>true</disableFixedJointLumping>
  </gazebo>
  <link name="/camera_tower_link">
    <visual>
      <origin rpy="0 0 0" xyz="0 0 0"/>
      <geometry>
        <mesh filename="package://interbotix_xslocobot_descriptions/meshes/locobot_meshes/kobuki_version/locobot_camera_tower_small.stl" scale="0.001 0.001 0.001"/>
      </geometry>
      <material name="interbotix_black"/>
    </visual>
    <collision>
      <origin rpy="0 0 0" xyz="0 0 0"/>
      <geometry>
        <mesh filename="package://interbotix_xslocobot_descriptions/meshes/locobot_meshes/kobuki_version/locobot_camera_tower_small_simple.stl" scale="0.001 0.001 0.001"/>
      </geometry>
    </collision>
    <inertial>
      <origin rpy="0 0 0" xyz="-0.0357703000 -0.0027068600 0.1560470000"/>
      <mass value="2.282808"/>
      <inertia ixx="0.0461600000" ixy="0.0002062000" ixz="0.0052560000" iyy="0.0384200000" iyz="-0.0003600000" izz="0.0169600000"/>
    </inertial>
  </link>
  <gazebo reference="/camera_tower_link">
    <material>Custom/Interbotix</material>
  </gazebo>
  <!-- base_type == 'kobuki' && camera_tower_size == 'small' -->
  <!-- base_type == 'kobuki' -->
  <!-- base_type == 'create3' -->
  <!-- ********************************** Pan & Tilt **********************************  -->
  <!-- base_type == 'kobuki' && camera_tower_size == 'large' -->
  <joint name="pan" type="revolute">
    <axis xyz="0 0 1"/>
    <limit effort="2" lower="-1.5707963267948966" upper="1.5707963267948966" velocity="3.141592653589793"/>
    <origin rpy="0 0 0" xyz="0.047228 0 0.38425"/>
    <parent link="/camera_tower_link"/>
    <child link="/pan_link"/>
  </joint>
  <transmission name="trans_pan">
    <type>transmission_interface/SimpleTransmission</type>
    <joint name="pan">
      <hardwareInterface>hardware_interface/EffortJointInterface</hardwareInterface>
    </joint>
    <actuator name="pan_motor">
      <mechanicalReduction>1</mechanicalReduction>
    </actuator>
  </transmission>
  <link name="/pan_link">
    <visual>
      <origin rpy="0 0 1.5707963267948966" xyz="0 0 0"/>
      <geometry>
        <mesh filename="package://interbotix_xslocobot_descriptions/meshes/locobot_meshes/locobot_pan.stl" scale="0.001 0.001 0.001"/>
      </geometry>
      <material name="interbotix_black"/>
    </visual>
    <collision>
      <origin rpy="0 0 1.5707963267948966" xyz="0 0 0"/>
      <geometry>
        <mesh filename="package://interbotix_xslocobot_descriptions/meshes/locobot_meshes/locobot_pan.stl" scale="0.001 0.001 0.001"/>
      </geometry>
    </collision>
    <inertial>
      <origin rpy="0 0 1.5707963267948966" xyz="0.012 0.000496 0.018504"/>
      <mass value="0.098997"/>
      <inertia ixx="0.0000276300" ixy="0.0000000418" ixz="0.0000005145" iyy="0.0000204300" iyz="-0.0000000421" izz="0.0000276300"/>
    </inertial>
  </link>
  <gazebo reference="/pan_link">
    <material>Custom/Interbotix</material>
    <self_collide>true</self_collide>
  </gazebo>
  <joint name="tilt" type="revolute">
    <axis xyz="0 1 0"/>
    <limit effort="2" lower="-1.5707963267948966" upper="1.3089969389957472" velocity="3.141592653589793"/>
    <origin rpy="0 0 0" xyz="0.025034 0 0.019"/>
    <parent link="/pan_link"/>
    <child link="/tilt_link"/>
  </joint>
  <transmission name="trans_tilt">
    <type>transmission_interface/SimpleTransmission</type>
    <joint name="tilt">
      <hardwareInterface>hardware_interface/EffortJointInterface</hardwareInterface>
    </joint>
    <actuator name="tilt_motor">
      <mechanicalReduction>1</mechanicalReduction>
    </actuator>
  </transmission>
  <link name="/tilt_link">
    <visual>
      <origin rpy="0 0 1.5707963267948966" xyz="0 0 0"/>
      <geometry>
        <mesh filename="package://interbotix_xslocobot_descriptions/meshes/locobot_meshes/locobot_tilt.stl" scale="0.001 0.001 0.001"/>
      </geometry>
      <material name="interbotix_black"/>
    </visual>
    <collision>
      <origin rpy="0 0 1.5707963267948966" xyz="0 0 0"/>
      <geometry>
        <mesh filename="package://interbotix_xslocobot_descriptions/meshes/locobot_meshes/locobot_tilt.stl" scale="0.001 0.001 0.001"/>
      </geometry>
    </collision>
    <inertial>
      <origin rpy="0 0 1.5707963267948966" xyz="0.0237737000 -0.0000016331 0.0000077432"/>
      <mass value="0.019845"/>
      <inertia ixx="0.0000021677" ixy="0.0000000000" ixz="0.0000000001" iyy="0.0000063634" iyz="0.0000000003" izz="0.0000066157"/>
    </inertial>
  </link>
  <gazebo reference="/tilt_link">
    <material>Custom/Interbotix</material>
    <self_collide>true</self_collide>
  </gazebo>
  <joint name="camera" type="fixed">
    <origin rpy="0 0 0" xyz="0.05318 0.0175 0.000009"/>
    <parent link="/tilt_link"/>
    <child link="/camera_link"/>
  </joint>
  <gazebo reference="camera">
    <disableFixedJointLumping>true</disableFixedJointLumping>
  </gazebo>
  <link name="/camera_link">
    <visual>
      <origin rpy="0 0 0" xyz="0 0 0"/>
      <geometry>
        <mesh filename="package://interbotix_xslocobot_descriptions/meshes/locobot_meshes/locobot_camera.stl" scale="0.001 0.001 0.001"/>
      </geometry>
      <material name="">
        <color rgba="0.55 0.55 0.55 1"/>
      </material>
    </visual>
    <collision>
      <origin rpy="0 0 0" xyz="0 0 0"/>
      <geometry>
        <mesh filename="package://interbotix_xslocobot_descriptions/meshes/locobot_meshes/locobot_camera.stl" scale="0.001 0.001 0.001"/>
      </geometry>
    </collision>
    <inertial>
      <origin rpy="0 0 0" xyz="-0.008972 -0.015818 0.000003"/>
      <mass value="0.072"/>
      <inertia ixx="0.0000465400" ixy="0.0000003028" ixz="0.0000000245" iyy="0.0000069128" iyz="0.0000000248" izz="0.0000468600"/>
    </inertial>
  </link>
  <gazebo reference="/camera_link">
    <material>Gazebo/Grey</material>
    <self_collide>true</self_collide>
  </gazebo>
  <!-- Adds a dummy link, libgazebo_ros_openni_kinect publishes from frame's z-axis -->
  <!-- https://github.com/ros-simulation/gazebo_ros_pkgs/issues/243 -->
  <joint name="camera_depth_joint" type="fixed">
    <origin rpy="-1.5707963267948966 0 -1.5707963267948966" xyz="0 0 0"/>
    <parent link="/camera_link"/>
    <child link="/camera_depth_link"/>
  </joint>
  <link name="/camera_depth_link">
    <origin rpy="0 0 0" xyz="0 0 0"/>
  </link>
  <gazebo reference="/camera_link">
    <sensor name="camera_frame_sensor" type="depth">
      <always_on>true</always_on>
      <update_rate>30.0</update_rate>
      <camera>
        <horizontal_fov>0.994837</horizontal_fov>
        <image>
          <format>R8G8B8</format>
          <width>640</width>
          <height>480</height>
        </image>
        <clip>
          <near>0.01</near>
          <far>10</far>
        </clip>
      </camera>
      <plugin filename="libgazebo_ros_openni_kinect.so" name="camera_frame_controller">
        <alwaysOn>true</alwaysOn>
        <updateRate>0.0</updateRate>
        <cameraName>camera</cameraName>
        <imageTopicName>color/image_raw</imageTopicName>
        <cameraInfoTopicName>color/camera_info</cameraInfoTopicName>
        <depthImageTopicName>aligned_depth_to_color/image_raw</depthImageTopicName>
        <depthImageCameraInfoTopicName>aligned_depth_to_color/camera_info</depthImageCameraInfoTopicName>
        <pointCloudTopicName>depth_registered/points</pointCloudTopicName>
        <frameName>/camera_depth_link</frameName>
        <pointCloudCutoff>0.01</pointCloudCutoff>
        <pointCloudCutoffMax>10</pointCloudCutoffMax>
        <distortionK1>0.00000001</distortionK1>
        <distortionK2>0.00000001</distortionK2>
        <distortionK3>0.00000001</distortionK3>
        <distortionT1>0.00000001</distortionT1>
        <distortionT2>0.00000001</distortionT2>
        <CxPrime>0</CxPrime>
        <Cx>0</Cx>
        <Cy>0</Cy>
        <focalLength>0</focalLength>
        <hackBaseline>0</hackBaseline>
      </plugin>
    </sensor>
  </gazebo>
  <!-- base_type == 'kobuki' && camera_tower_size == 'small' -->
  <!-- base_type == 'kobuki' -->
  <!-- base_type == 'create3' -->
  <!-- ********************************** Lidar **********************************  -->
  <!-- base_type == 'kobuki' && camera_tower_size == 'large' -->
  <joint name="lidar_tower" type="fixed">
    <origin rpy="0 0 0" xyz="-0.074 0 0.38425"/>
    <parent link="/camera_tower_link"/>
    <child link="/lidar_tower_link"/>
  </joint>
  <link name="/lidar_tower_link">
    <visual>
      <origin rpy="0 0 0" xyz="0 0 0"/>
      <geometry>
        <mesh filename="package://interbotix_xslocobot_descriptions/meshes/locobot_meshes/locobot_lidar_tower.stl" scale="0.001 0.001 0.001"/>
      </geometry>
      <material name="interbotix_black"/>
    </visual>
    <collision>
      <origin rpy="0 0 0" xyz="0 0 0"/>
      <geometry>
        <mesh filename="package://interbotix_xslocobot_descriptions/meshes/locobot_meshes/locobot_lidar_tower_simple.stl" scale="0.001 0.001 0.001"/>
      </geometry>
    </collision>
    <inertial>
      <origin rpy="0 0 0" xyz="-0.0074822400 -0.0000196881 0.0507957000"/>
      <mass value="0.155485"/>
      <inertia ixx="0.0007642000" ixy="-0.0000001357" ixz="0.0000134700" iyy="0.0001285000" iyz="0.0000000354" izz="0.0007840000"/>
    </inertial>
  </link>
  <gazebo reference="/lidar_tower_link">
    <material>Custom/Interbotix</material>
  </gazebo>
  <gazebo reference="lidar_tower">
    <disableFixedJointLumping>true</disableFixedJointLumping>
  </gazebo>
  <joint name="lidar" type="fixed">
    <origin rpy="0 0 3.141592653589793" xyz="0 0 0.09425"/>
    <parent link="/lidar_tower_link"/>
    <child link="/laser_frame_link"/>
  </joint>
  <gazebo reference="lidar">
    <disableFixedJointLumping>true</disableFixedJointLumping>
  </gazebo>
  <link name="/laser_frame_link">
    <visual>
      <origin rpy="0 0 0" xyz="0 0 0"/>
      <geometry>
        <mesh filename="package://interbotix_xslocobot_descriptions/meshes/locobot_meshes/locobot_lidar.stl" scale="0.001 0.001 0.001"/>
      </geometry>
      <material name="interbotix_black"/>
    </visual>
    <collision>
      <origin rpy="0 0 0" xyz="0 0 -0.0091"/>
      <geometry>
        <cylinder length="0.0408" radius="0.03785"/>
      </geometry>
    </collision>
    <inertial>
      <origin rpy="0 0 0" xyz="0.0007379970 0 -0.0103809000"/>
      <mass value="0.196"/>
      <inertia ixx="0.0000907500" ixy="0.0000000001" ixz="-0.0000014234" iyy="0.0000877600" iyz="0" izz="0.0001268000"/>
    </inertial>
  </link>
  <gazebo reference="/laser_frame_link">
    <material>Custom/Interbotix</material>
    <sensor name="rplidar" type="ray">
      <pose>0 0 0 0 0 0</pose>
      <visualize>false</visualize>
      <update_rate>30</update_rate>
      <ray>
        <scan>
          <horizontal>
            <samples>400</samples>
            <resolution>1</resolution>
            <min_angle>-3.14159</min_angle>
            <max_angle>3.14159</max_angle>
          </horizontal>
        </scan>
        <range>
          <min>0.2</min>
          <max>16.0</max>
          <resolution>0.02</resolution>
        </range>
        <noise>
          <type>gaussian</type>
          <mean>0.0</mean>
          <stddev>0.01</stddev>
        </noise>
      </ray>
      <plugin filename="libgazebo_ros_laser.so" name="gazebo_ros_head_rplidar_controller">
        <topicName>scan</topicName>
        <frameName>/laser_frame_link</frameName>
      </plugin>
    </sensor>
  </gazebo>
  <!-- base_type == 'kobuki' && camera_tower_size == 'small' -->
  <!-- base_type == 'kobuki' -->
  <!-- base_type == 'create3' -->
  <!-- show_lidar -->
</robot>

